<?xml version="1.0"?>
<robot xmlns:xacro="http://www.ros.org/wiki/xacro" name="robot">
    <material name="blue">
        <color rgba="0.2 0.2 1 1"/>
    </material>

    <link name="world"></link>

    <joint name="base_joint" type="fixed">
        <origin xyz="1.5 1.0 0" rpy="0 0 0"/>
        <parent link="world"/>
        <child link="base_link"/>        
    </joint>

    <link name="base_link">
        <visual>
            <origin xyz="0 0 0.05" rpy="0 0 0"/>
            <geometry>
                <box size="2.5 1.5 0.1" />
            </geometry>
            <material name="green">
                <color rgba="0.2 1 0.2 1"/>
            </material>
        </visual>
        <collision>
            <origin xyz="0 0 0.05" rpy="0 0 0"/>
            <geometry>
                <box size="2.5 1.5 0.1" />
            </geometry>
        </collision>
        <inertial>
            <origin xyz="0 0 0.05" rpy="0 0 0"/>
            <mass value="12" />
            <inertia ixx="2.26" ixy="0.0" ixz="0.0" iyy="6.26" iyz="0.0" izz="8.5" />
        </inertial>
    </link>

    <joint name="slider_joint" type="prismatic">
        <origin rpy="0 0 0" xyz="-1.25 0 0.1"/>
        <parent link="base_link"/>
        <child link="slider_link"/>
        <axis xyz="1 0 0"/>
        <limit effort="100" lower="0" upper="2" velocity="100"/>
      </joint>

      <link name="slider_link">
        <visual>
          <origin rpy="0 0 0" xyz="0 0 0.075"/>
          <geometry>
            <box size="0.5 0.25 0.15"/>
          </geometry>
          <material name="blue"/>
        </visual>
        <collision>
          <origin rpy="0 0 0" xyz="0 0 0.075"/>
          <geometry>
            <box size="0.5 0.25 0.15"/>
          </geometry>
        </collision>
        <inertial>
          <origin rpy="0 0 0" xyz="0 0 0.075"/>
          <mass value="0.5"/>
          <inertia ixx="0.003541666666666666" ixy="0.0" ixz="0.0" iyy="0.011354166666666667" iyz="0.0" izz="0.013020833333333332"/>
        </inertial>
      </link>

</robot>